Workbook

Sheet HuongDan
A1: HƯỚNG DẪN: BỘ DỮ LIỆU GỢI Ý TRANG PHỤC (RF HỒI QUY VÀ KNN)
A3: 1. BÀI TOÁN
A4: Mục tiêu | B4: Cho 1 món trang phục + 1 hoàn cảnh + nhiệt độ ngày hôm nay, mô hình dự đoán "Điểm phù hợp" từ 0 đến 10. Điểm càng cao thì càng nên mặc.
A6: 2. CÁC SHEET
A7: MonDo | B7: Danh mục 1500 món, mỗi dòng 1 món, kèm 4 cột Điểm phù hợp (điểm của món ở từng hoàn cảnh khi trời nằm trong khoảng nhiệt của món) và Hoàn cảnh hợp nhất. Dùng để xem, lọc theo giới tính, loại, mùa, phong cách và mở link ảnh.
A8: DuLieu_ML | B8: Bộ dữ liệu để huấn luyện: 6000 dòng = 1500 món × 4 hoàn cảnh. Mỗi dòng có 1 nhiệt độ ngày ngẫu nhiên từ 5 đến 40°C. Dòng đã xáo trộn.
A9: CachTinhDiem | B9: Toàn bộ trọng số, bảng chấm, tham số và Máy tính thử. Sửa ô vàng thì điểm tự tính lại.
A10: KiemChung | B10: 100 tình huống để nhờ người thật chấm, so với công thức.
A11: ThongKe | B11: Số lượng và phân bố điểm, tự tính.
A13: 3. MÀU TIÊU ĐỀ
A14: Xanh dương nhạt | B14: ĐẦU VÀO của mô hình, 9 cột: Hoàn cảnh, Phong cách, Tmin, Tmax, Nhiệt độ ngày, Giữ ấm, Thoáng khí, Vận động, Chỉn chu.
A15: Xanh lá | B15: ĐẦU RA cần dự đoán: Điểm phù hợp (0–10) ở sheet DuLieu_ML (đã xét nhiệt độ ngày). Ở sheet MonDo có 4 cột Điểm phù hợp theo hoàn cảnh, chưa xét nhiệt độ ngày, để xem nhanh món hợp chỗ nào.
A16: Cam | B16: Cột trung gian và cột Tập. KHÔNG đưa vào mô hình: các cột Bước 1, 2, 3 dùng để tính ra điểm, đưa vào sẽ lộ đáp án.
A17: Vàng nhạt (MonDo) | B17: Cột dùng để lọc khi gợi ý (Loại TP, Giới tính, Mùa), không đưa vào mô hình.
A18: Xám | B18: Chỉ để hiển thị hoặc làm khóa nối (ID_SP, tên, màu, họa tiết, chất liệu, link).
A20: 4. CÁCH TÍNH ĐIỂM (3 BƯỚC, MỖI BƯỚC 1 CỘT)
A21: Bước 1: Điểm hoàn cảnh | B21: Chấm 4 đặc tính của món (Giữ ấm, Thoáng khí, Vận động, Chỉn chu, thang 1–5) rồi lấy trung bình có trọng số theo hoàn cảnh (ví dụ Thuyết trình: 60% Chỉn chu). Đặc tính dựa trên chất liệu và kiểu dáng với cơ sở: độ cách nhiệt clo (ISO 9920), thoát hơi nước (ISO 11092), độ thấm khí (ISO 9237), ergonomics và dress code học thuật.
A22: Bước 2: Điểm phong cách | B22: Tra bảng độ hợp giữa phong cách và hoàn cảnh (quy ước ăn mặc): ví dụ Smart Casual rất hợp Thuyết trình, Sporty không hợp.
A23: Bước 3: Hệ số nhiệt độ | B23: Nếu nhiệt độ ngày nằm trong khoảng Tmin–Tmax của món thì hệ số = 1. Ngoài khoảng, mỗi °C lệch trừ 10%; lệch từ 10°C trở lên thì hệ số = 0. Cơ sở: khái niệm vùng nhiệt thoải mái của quần áo (ISO 9920, ISO 7730).
A24: Công thức cuối | B24: Điểm phù hợp = (70% × Bước 1 + 30% × Bước 2) × Bước 3, làm tròn 1 chữ số. Xem Máy tính thử ở sheet CachTinhDiem.
A26: 5. CÁCH DÙNG VỚI RF VÀ KNN
A27: Đầu vào và đầu ra | B27: X = 9 cột xanh dương (Hoàn cảnh và Phong cách chuyển thành one-hot); y = Điểm phù hợp.
A28: Chia dữ liệu | B28: Dùng cột Tập (Train khoảng 80%, Test khoảng 20%). Cột này chia theo nhóm món: cả 4 dòng của một món, và các món giống hệt nhau chỉ khác màu, luôn nằm cùng một phía, nên kết quả không bị đẹp giả.
A29: Thiết lập | B29: KNN: chuẩn hóa dữ liệu (StandardScaler), thử K = 3, 5, 10, 15. RF: thử 100–300 cây.
A30: Đánh giá | B30: Dùng MAE (sai số tính bằng điểm), RMSE, R², và so với mốc "luôn đoán điểm trung bình".
A31: Kết quả chạy thử (tham khảo) | B31: Mốc đoán trung bình: MAE khoảng 2.3. RF (200 cây): MAE khoảng 0.3, R² khoảng 0.97. KNN (K = 5): MAE khoảng 0.75, R² khoảng 0.8. RF tốt hơn vì điểm phụ thuộc vào tương tác giữa nhiệt độ ngày và khoảng Tmin–Tmax, còn KNN bị nhiễu bởi nhiều cột one-hot.
A33: 6. CÁCH GỢI Ý CHO NGƯỜI DÙNG
A34: Quy trình | B34: Người dùng chọn giới tính, phong cách (nếu muốn), hoàn cảnh và nhập nhiệt độ hôm nay. Hệ thống lọc MonDo theo giới tính (cả Unisex) và phong cách, mô hình dự đoán điểm từng món cho tình huống đó, rồi xếp hạng và lấy các món điểm cao nhất.
A36: 7. HẠN CHẾ (NÊN NÓI THẲNG TRONG BÁO CÁO)
A37: Nhãn là công thức | B37: Điểm tính bằng công thức, nên R² cao (RF khoảng 0.97) chủ yếu là mô hình học lại công thức; thể hiện được khả năng khái quát cho món và nhiệt độ mới. Giá trị thật cần kiểm chứng bằng sheet KiemChung.
A38: Tham số do nhóm đặt | B38: Trọng số, bảng phong cách và mức trừ 10%/°C là ước lượng của nhóm dựa trên quy ước, chưa đo thực nghiệm.
A39: Nhiệt độ ngày | B39: Chọn ngẫu nhiên đều 5–40°C cho mỗi dòng, nên khoảng 21% dòng có điểm bằng 0 (trời quá lạnh hoặc quá nóng so với món). Đây là phần mô hình cần học.
A40: Chưa xét mưa, gió | B40: Đã bỏ Chống mưa, Cản gió để gọn. Vì vậy bộ dữ liệu không có đồ đi mưa (áo mưa, quần đi mưa, giày/dép đi mưa); các món này đã được thay bằng trang phục thông thường cùng loại, cùng giới tính.
A41: Lệch giới và phong cách | B41: Váy, đầm chỉ có ở Nữ; Artsy chủ yếu là đồ Nữ. Phản ánh thực tế nhưng dự đoán cho Nam–Artsy sẽ kém tin cậy hơn.

Sheet MonDo
A1: ID_SP | B1: Loại TP | C1: Tên trang phục | D1: Giới tính | E1: Màu sắc | F1: Họa tiết | G1: Chất liệu | H1: Tmin (°C) | I1: Tmax (°C) | J1: Mùa | K1: Giữ ấm | L1: Thoáng khí | M1: Vận động | N1: Chỉn chu | O1: Phong cách | P1: Điểm phù hợp: Đi học | Q1: Điểm phù hợp: Xưởng/Công trình | R1: Điểm phù hợp: Vẽ ngoại cảnh | S1: Điểm phù hợp: Thuyết trình | T1: Hoàn cảnh hợp nhất | U1: Link Google | V1: Link Pinterest
A2: SP0001 | B2: Áo | C2: Áo thun oversize thun cotton màu vàng | D2: Nam | E2: Vàng | F2: Trơn | G2: thun cotton | H2: 20 | I2: 38 | J2: Xuân, Hạ, Thu | K2: 2 | L2: 5 | M2: 2 | N2: 2 | O2: Streetwear | P2: =ROUND(CachTinhDiem!$B$23*ROUND(1+(SUMPRODUCT(INDEX(CachTinhDiem!$B$8:$E$11,1,0),$K2:$N2)-1)*9/4,1)+CachTinhDiem!$B$24*ROUND(1+(INDEX(CachTinhDiem!$B$15:$E$20,MATCH($O2,CachTinhDiem!$A$15:$A$20,0),1)-1)*9/4,1),1) -> 6.1 | Q2: =ROUND(CachTinhDiem!$B$23*ROUND(1+(SUMPRODUCT(INDEX(CachTinhDiem!$B$8:$E$11,2,0),$K2:$N2)-1)*9/4,1)+CachTinhDiem!$B$24*ROUND(1+(INDEX(CachTinhDiem!$B$15:$E$20,MATCH($O2,CachTinhDiem!$A$15:$A$20,0),2)-1)*9/4,1),1) -> 4.9 | R2: =ROUND(CachTinhDiem!$B$23*ROUND(1+(SUMPRODUCT(INDEX(CachTinhDiem!$B$8:$E$11,3,0),$K2:$N2)-1)*9/4,1)+CachTinhDiem!$B$24*ROUND(1+(INDEX(CachTinhDiem!$B$15:$E$20,MATCH($O2,CachTinhDiem!$A$15:$A$20,0),3)-1)*9/4,1),1) -> 6.1 | S2: =ROUND(CachTinhDiem!$B$23*ROUND(1+(SUMPRODUCT(INDEX(CachTinhDiem!$B$8:$E$11,4,0),$K2:$N2)-1)*9/4,1)+CachTinhDiem!$B$24*ROUND(1+(INDEX(CachTinhDiem!$B$15:$E$20,MATCH($O2,CachTinhDiem!$A$15:$A$20,0),4)-1)*9/4,1),1) -> 4.2 | T2: =INDEX(CachTinhDiem!$A$8:$A$11,MATCH(MAX($P2:$S2),$P2:$S2,0)) -> Đi học | U2: Google | V2: Pinterest
A3: SP0002 | B3: Áo | C3: Áo sweatshirt nỉ bông màu be sữa | D3: Nam | E3: Be sữa | F3: Trơn | G3: nỉ bông | H3: 8 | I3: 22 | J3: Xuân, Đông | K3: 4 | L3: 2 | M3: 3 | N3: 3 | O3: Streetwear | P3: =ROUND(CachTinhDiem!$B$23*ROUND(1+(SUMPRODUCT(INDEX(CachTinhDiem!$B$8:$E$11,1,0),$K3:$N3)-1)*9/4,1)+CachTinhDiem!$B$24*ROUND(1+(INDEX(CachTinhDiem!$B$15:$E$20,MATCH($O3,CachTinhDiem!$A$15:$A$20,0),1)-1)*9/4,1),1) -> 5.9 | Q3: =ROUND(CachTinhDiem!$B$23*ROUND(1+(SUMPRODUCT(INDEX(CachTinhDiem!$B$8:$E$11,2,0),$K3:$N3)-1)*9/4,1)+CachTinhDiem!$B$24*ROUND(1+(INDEX(CachTinhDiem!$B$15:$E$20,MATCH($O3,CachTinhDiem!$A$15:$A$20,0),2)-1)*9/4,1),1) -> 5.5 | R3: =ROUND(CachTinhDiem!$B$23*ROUND(1+(SUMPRODUCT(INDEX(CachTinhDiem!$B$8:$E$11,3,0),$K3:$N3)-1)*9/4,1)+CachTinhDiem!$B$24*ROUND(1+(INDEX(CachTinhDiem!$B$15:$E$20,MATCH($O3,CachTinhDiem!$A$15:$A$20,0),3)-1)*9/4,1),1) -> 5.7 | S3: =ROUND(CachTinhDiem!$B$23*ROUND(1+(SUMPRODUCT(INDEX(CachTinhDiem!$B$8:$E$11,4,0),$K3:$N3)-1)*9/4,1)+CachTinhDiem!$B$24*ROUND(1+(INDEX(CachTinhDiem!$B$15:$E$20,MATCH($O3,CachTinhDiem!$A$15:$A$20,0),4)-1)*9/4,1),1) -> 4.6 | T3: =INDEX(CachTinhDiem!$A$8:$A$11,MATCH(MAX($P3:$S3),$P3:$S3,0)) -> Đi học | U3: Google | V3: Pinterest
A4: SP0003 | B4: Áo | C4: Áo blouse công sở satin màu xanh mint | D4: Nữ | E4: Xanh mint | F4: Trơn | G4: satin | H4: 21 | I4: 35 | J4: Xuân, Hạ, Thu | K4: 1 | L4: 3 | M4: 3 | N4: 4 | O4: Smart Casual | P4: =ROUND(CachTinhDiem!$B$23*ROUND(1+(SUMPRODUCT(INDEX(CachTinhDiem!$B$8:$E$11,1,0),$K4:$N4)-1)*9/4,1)+CachTinhDiem!$B$24*ROUND(1+(INDEX(CachTinhDiem!$B$15:$E$20,MATCH($O4,CachTinhDiem!$A$15:$A$20,0),1)-1)*9/4,1),1) -> 6.3 | Q4: =ROUND(CachTinhDiem!$B$23*ROUND(1+(SUMPRODUCT(INDEX(CachTinhDiem!$B$8:$E$11,2,0),$K4:$N4)-1)*9/4,1)+CachTinhDiem!$B$24*ROUND(1+(INDEX(CachTinhDiem!$B$15:$E$20,MATCH($O4,CachTinhDiem!$A$15:$A$20,0),2)-1)*9/4,1),1) -> 4.4 | R4: =ROUND(CachTinhDiem!$B$23*ROUND(1+(SUMPRODUCT(INDEX(CachTinhDiem!$B$8:$E$11,3,0),$K4:$N4)-1)*9/4,1)+CachTinhDiem!$B$24*ROUND(1+(INDEX(CachTinhDiem!$B$15:$E$20,MATCH($O4,CachTinhDiem!$A$15:$A$20,0),3)-1)*9/4,1),1) -> 5.2 | S4: =ROUND(CachTinhDiem!$B$23*ROUND(1+(SUMPRODUCT(INDEX(CachTinhDiem!$B$8:$E$11,4,0),$K4:$N4)-1)*9/4,1)+CachTinhDiem!$B$24*ROUND(1+(INDEX(CachTinhDiem!$B$15:$E$20,MATCH($O4,CachTinhDiem!$A$15:$A$20,0),4)-1)*9/4,1),1) -> 7.8 | T4: =INDEX(CachTinhDiem!$A$8:$A$11,MATCH(MAX($P4:$S4),$P4:$S4,0)) -> Thuyết trình | U4: Google | V4: Pinterest
A5: SP0004 | B5: Áo | C5: Áo thun oversize thun cotton màu đen | D5: Nam | E5: Đen | F5: Trơn | G5: thun cotton | H5: 20 | I5: 37 | J5: Xuân, Hạ, Thu | K5: 2 | L5: 5 | M5: 3 | N5: 2 | O5: Streetwear | P5: =ROUND(CachTinhDiem!$B$23*ROUND(1+(SUMPRODUCT(INDEX(CachTinhDiem!$B$8:$E$11,1,0),$K5:$N5)-1)*9/4,1)+CachTinhDiem!$B$24*ROUND(1+(INDEX(CachTinhDiem!$B$15:$E$20,MATCH($O5,CachTinhDiem!$A$15:$A$20,0),1)-1)*9/4,1),1) -> 6.5 | Q5: =ROUND(CachTinhDiem!$B$23*ROUND(1+(SUMPRODUCT(INDEX(CachTinhDiem!$B$8:$E$11,2,0),$K5:$N5)-1)*9/4,1)+CachTinhDiem!$B$24*ROUND(1+(INDEX(CachTinhDiem!$B$15:$E$20,MATCH($O5,CachTinhDiem!$A$15:$A$20,0),2)-1)*9/4,1),1) -> 5.6 | R5: =ROUND(CachTinhDiem!$B$23*ROUND(1+(SUMPRODUCT(INDEX(CachTinhDiem!$B$8:$E$11,3,0),$K5:$N5)-1)*9/4,1)+CachTinhDiem!$B$24*ROUND(1+(INDEX(CachTinhDiem!$B$15:$E$20,MATCH($O5,CachTinhDiem!$A$15:$A$20,0),3)-1)*9/4,1),1) -> 6.8 | S5: =ROUND(CachTinhDiem!$B$23*ROUND(1+(SUMPRODUCT(INDEX(CachTinhDiem!$B$8:$E$11,4,0),$K5:$N5)-1)*9/4,1)+CachTinhDiem!$B$24*ROUND(1+(INDEX(CachTinhDiem!$B$15:$E$20,MATCH($O5,CachTinhDiem!$A$15:$A$20,0),4)-1)*9/4,1),1) -> 4.6 | T5: =INDEX(CachTinhDiem!$A$8:$A$11,MATCH(MAX($P5:$S5),$P5:$S5,0)) -> Vẽ ngoại cảnh | U5: Google | V5: Pinterest
A6: SP0005 | B6: Áo | C6: Áo thun cổ tròn cotton compact màu xám | D6: Nam | E6: Xám | F6: Trơn | G6: cotton compact | H6: 20 | I6: 37 | J6: Xuân, Hạ, Thu | K6: 2 | L6: 4 | M6: 3 | N6: 2 | O6: Minimalist | P6: =ROUND(CachTinhDiem!$B$23*ROUND(1+(SUMPRODUCT(INDEX(CachTinhDiem!$B$8:$E$11,1,0),$K6:$N6)-1)*9/4,1)+CachTinhDiem!$B$24*ROUND(1+(INDEX(CachTinhDiem!$B$15:$E$20,MATCH($O6,CachTinhDiem!$A$15:$A$20,0),1)-1)*9/4,1),1) -> 6.1 | Q6: =ROUND(CachTinhDiem!$B$23*ROUND(1+(SUMPRODUCT(INDEX(CachTinhDiem!$B$8:$E$11,2,0),$K6:$N6)-1)*9/4,1)+CachTinhDiem!$B$24*ROUND(1+(INDEX(CachTinhDiem!$B$15:$E$20,MATCH($O6,CachTinhDiem!$A$15:$A$20,0),2)-1)*9/4,1),1) -> 5.4 | R6: =ROUND(CachTinhDiem!$B$23*ROUND(1+(SUMPRODUCT(INDEX(CachTinhDiem!$B$8:$E$11,3,0),$K6:$N6)-1)*9/4,1)+CachTinhDiem!$B$24*ROUND(1+(INDEX(CachTinhDiem!$B$15:$E$20,MATCH($O6,CachTinhDiem!$A$15:$A$20,0),3)-1)*9/4,1),1) -> 5.6 | S6: =ROUND(CachTinhDiem!$B$23*ROUND(1+(SUMPRODUCT(INDEX(CachTinhDiem!$B$8:$E$11,4,0),$K6:$N6)-1)*9/4,1)+CachTinhDiem!$B$24*ROUND(1+(INDEX(CachTinhDiem!$B$15:$E$20,MATCH($O6,CachTinhDiem!$A$15:$A$20,0),4)-1)*9/4,1),1) -> 5.6 | T6: =INDEX(CachTinhDiem!$A$8:$A$11,MATCH(MAX($P6:$S6),$P6:$S6,0)) -> Đi học | U6: Google | V6: Pinterest
A7: SP0006 | B7: Áo | C7: Áo polo cotton pique màu đỏ đô | D7: Nam | E7: Đỏ đô | F7: Trơn | G7: cotton pique | H7: 20 | I7: 38 | J7: Xuân, Hạ, Thu | K7: 2 | L7: 5 | M7: 3 | N7: 4 | O7: Casual | P7: =ROUND(CachTinhDiem!$B$23*ROUND(1+(SUMPRODUCT(INDEX(CachTinhDiem!$B$8:$E$11,1,0),$K7:$N7)-1)*9/4,1)+CachTinhDiem!$B$24*ROUND(1+(INDEX(CachTinhDiem!$B$15:$E$20,MATCH($O7,CachTinhDiem!$A$15:$A$20,0),1)-1)*9/4,1),1) -> 8.1 | Q7: =ROUND(CachTinhDiem!$B$23*ROUND(1+(SUMPRODUCT(INDEX(CachTinhDiem!$B$8:$E$11,2,0),$K7:$N7)-1)*9/4,1)+CachTinhDiem!$B$24*ROUND(1+(INDEX(CachTinhDiem!$B$15:$E$20,MATCH($O7,CachTinhDiem!$A$15:$A$20,0),2)-1)*9/4,1),1) -> 6.7 | R7: =ROUND(CachTinhDiem!$B$23*ROUND(1+(SUMPRODUCT(INDEX(CachTinhDiem!$B$8:$E$11,3,0),$K7:$N7)-1)*9/4,1)+CachTinhDiem!$B$24*ROUND(1+(INDEX(CachTinhDiem!$B$15:$E$20,MATCH($O7,CachTinhDiem!$A$15:$A$20,0),3)-1)*9/4,1),1) -> 8.1 | S7: =ROUND(CachTinhDiem!$B$23*ROUND(1+(SUMPRODUCT(INDEX(CachTinhDiem!$B$8:$E$11,4,0),$K7:$N7)-1)*9/4,1)+CachTinhDiem!$B$24*ROUND(1+(INDEX(CachTinhDiem!$B$15:$E$20,MATCH($O7,CachTinhDiem!$A$15:$A$20,0),4)-1)*9/4,1),1) -> 7.1 | T7: =INDEX(CachTinhDiem!$A$8:$A$11,MATCH(MAX($P7:$S7),$P7:$S7,0)) -> Đi học | U7: Google | V7: Pinterest
A8: SP0007 | B8: Áo | C8: Áo sơ mi flannel họa tiết caro xám | D8: Nam | E8: Xám | F8: Caro | G8: flannel | H8: 6 | I8: 18 | J8: Đông | K8: 4 | L8: 3 | M8: 3 | N8: 2 | O8: Streetwear | P8: =ROUND(CachTinhDiem!$B$23*ROUND(1+(SUMPRODUCT(INDEX(CachTinhDiem!$B$8:$E$11,1,0),$K8:$N8)-1)*9/4,1)+CachTinhDiem!$B$24*ROUND(1+(INDEX(CachTinhDiem!$B$15:$E$20,MATCH($O8,CachTinhDiem!$A$15:$A$20,0),1)-1)*9/4,1),1) -> 5.9 | Q8: =ROUND(CachTinhDiem!$B$23*ROUND(1+(SUMPRODUCT(INDEX(CachTinhDiem!$B$8:$E$11,2,0),$K8:$N8)-1)*9/4,1)+CachTinhDiem!$B$24*ROUND(1+(INDEX(CachTinhDiem!$B$15:$E$20,MATCH($O8,CachTinhDiem!$A$15:$A$20,0),2)-1)*9/4,1),1) -> 5.6 | R8: =ROUND(CachTinhDiem!$B$23*ROUND(1+(SUMPRODUCT(INDEX(CachTinhDiem!$B$8:$E$11,3,0),$K8:$N8)-1)*9/4,1)+CachTinhDiem!$B$24*ROUND(1+(INDEX(CachTinhDiem!$B$15:$E$20,MATCH($O8,CachTinhDiem!$A$15:$A$20,0),3)-1)*9/4,1),1) -> 5.9 | S8: =ROUND(CachTinhDiem!$B$23*ROUND(1+(SUMPRODUCT(INDEX(CachTinhDiem!$B$8:$E$11,4,0),$K8:$N8)-1)*9/4,1)+CachTinhDiem!$B$24*ROUND(1+(INDEX(CachTinhDiem!$B$15:$E$20,MATCH($O8,CachTinhDiem!$A$15:$A$20,0),4)-1)*9/4,1),1) -> 3.9 | T8: =INDEX(CachTinhDiem!$A$8:$A$11,MATCH(MAX($P8:$S8),$P8:$S8,0)) -> Đi học | U8: Google | V8: Pinterest
A9: SP0008 | B9: Áo | C9: Áo len cổ lọ len dệt kim màu đỏ đô | D9: Nữ | E9: Đỏ đô | F9: Trơn | G9: len dệt kim | H9: 5 | I9: 14 | J9: Đông | K9: 4 | L9: 1 | M9: 2 | N9: 3 | O9: Minimalist | P9: =ROUND(CachTinhDiem!$B$23*ROUND(1+(SUMPRODUCT(INDEX(CachTinhDiem!$B$8:$E$11,1,0),$K9:$N9)-1)*9/4,1)+CachTinhDiem!$B$24*ROUND(1+(INDEX(CachTinhDiem!$B$15:$E$20,MATCH($O9,CachTinhDiem!$A$15:$A$20,0),1)-1)*9/4,1),1) -> 4.9 | Q9: =ROUND(CachTinhDiem!$B$23*ROUND(1+(SUMPRODUCT(INDEX(CachTinhDiem!$B$8:$E$11,2,0),$K9:$N9)-1)*9/4,1)+CachTinhDiem!$B$24*ROUND(1+(INDEX(CachTinhDiem!$B$15:$E$20,MATCH($O9,CachTinhDiem!$A$15:$A$20,0),2)-1)*9/4,1),1) -> 4.4 | R9: =ROUND(CachTinhDiem!$B$23*ROUND(1+(SUMPRODUCT(INDEX(CachTinhDiem!$B$8:$E$11,3,0),$K9:$N9)-1)*9/4,1)+CachTinhDiem!$B$24*ROUND(1+(INDEX(CachTinhDiem!$B$15:$E$20,MATCH($O9,CachTinhDiem!$A$15:$A$20,0),3)-1)*9/4,1),1) -> 3.8 | S9: =ROUND(CachTinhDiem!$B$23*ROUND(1+(SUMPRODUCT(INDEX(CachTinhDiem!$B$8:$E$11,4,0),$K9:$N9)-1)*9/4,1)+CachTinhDiem!$B$24*ROUND(1+(INDEX(CachTinhDiem!$B$15:$E$20,MATCH($O9,CachTinhDiem!$A$15:$A$20,0),4)-1)*9/4,1),1) -> 5.3 | T9: =INDEX(CachTinhDiem!$A$8:$A$11,MATCH(MAX($P9:$S9),$P9:$S9,0)) -> Thuyết trình | U9: Google | V9: Pinterest
A10: SP0009 | B10: Áo | C10: Áo thun tay dài basic modal màu vàng mustard | D10: Nam | E10: Vàng mustard | F10: Trơn | G10: modal | H10: 15 | I10: 30 | J10: Xuân, Thu | K10: 2 | L10: 4 | M10: 4 | N10: 2 | O10: Minimalist | P10: =ROUND(CachTinhDiem!$B$23*ROUND(1+(SUMPRODUCT(INDEX(CachTinhDiem!$B$8:$E$11,1,0),$K10:$N10)-1)*9/4,1)+CachTinhDiem!$B$24*ROUND(1+(INDEX(CachTinhDiem!$B$15:$E$20,MATCH($O10,CachTinhDiem!$A$15:$A$20,0),1)-1)*9/4,1),1) -> 6.5 | Q10: =ROUND(CachTinhDiem!$B$23*ROUND(1+(SUMPRODUCT(INDEX(CachTinhDiem!$B$8:$E$11,2,0),$K10:$N10)-1)*9/4,1)+CachTinhDiem!$B$24*ROUND(1+(INDEX(CachTinhDiem!$B$15:$E$20,MATCH($O10,CachTinhDiem!$A$15:$A$20,0),2)-1)*9/4,1),1) -> 6.1 | R10: =ROUND(CachTinhDiem!$B$23*ROUND(1+(SUMPRODUCT(INDEX(CachTinhDiem!$B$8:$E$11,3,0),$K10:$N10)-1)*9/4,1)+CachTinhDiem!$B$24*ROUND(1+(INDEX(CachTinhDiem!$B$15:$E$20,MATCH($O10,CachTinhDiem!$A$15:$A$20,0),3)-1)*9/4,1),1) -> 6.5 | S10: =ROUND(CachTinhDiem!$B$23*ROUND(1+(SUMPRODUCT(INDEX(CachTinhDiem!$B$8:$E$11,4,0),$K10:$N10)-1)*9/4,1)+CachTinhDiem!$B$24*ROUND(1+(INDEX(CachTinhDiem!$B$15:$E$20,MATCH($O10,CachTinhDiem!$A$15:$A$20,0),4)-1)*9/4,1),1) -> 5.9 | T10: =INDEX(CachTinhDiem!$A$8:$A$11,MATCH(MAX($P10:$S10),$P10:$S10,0)) -> Đi học | U10: Google | V10: Pinterest
A11: SP0010 | B11: Áo | C11: Áo sơ mi ngắn tay cotton màu xanh navy | D11: Nam | E11: Xanh navy | F11: Trơn | G11: cotton | H11: 23 | I11: 40 | J11: Hạ, Thu | K11: 2 | L11: 5 | M11: 2 | N11: 4 | O11: Casual | P11: =ROUND(CachTinhDiem!$B$23*ROUND(1+(SUMPRODUCT(INDEX(CachTinhDiem!$B$8:$E$11,1,0),$K11:$N11)-1)*9/4,1)+CachTinhDiem!$B$24*ROUND(1+(INDEX(CachTinhDiem!$B$15:$E$20,MATCH($O11,CachTinhDiem!$A$15:$A$20,0),1)-1)*9/4,1),1) -> 7.6 | Q11: =ROUND(CachTinhDiem!$B$23*ROUND(1+(SUMPRODUCT(INDEX(CachTinhDiem!$B$8:$E$11,2,0),$K11:$N11)-1)*9/4,1)+CachTinhDiem!$B$24*ROUND(1+(INDEX(CachTinhDiem!$B$15:$E$20,MATCH($O11,CachTinhDiem!$A$15:$A$20,0),2)-1)*9/4,1),1) -> 5.9 | R11: =ROUND(CachTinhDiem!$B$23*ROUND(1+(SUMPRODUCT(INDEX(CachTinhDiem!$B$8:$E$11,3,0),$K11:$N11)-1)*9/4,1)+CachTinhDiem!$B$24*ROUND(1+(INDEX(CachTinhDiem!$B$15:$E$20,MATCH($O11,CachTinhDiem!$A$15:$A$20,0),3)-1)*9/4,1),1) -> 7.3 | S11: =ROUND(CachTinhDiem!$B$23*ROUND(1+(SUMPRODUCT(INDEX(CachTinhDiem!$B$8:$E$11,4,0),$K11:$N11)-1)*9/4,1)+CachTinhDiem!$B$24*ROUND(1+(INDEX(CachTinhDiem!$B$15:$E$20,MATCH($O11,CachTinhDiem!$A$15:$A$20,0),4)-1)*9/4,1),1) -> 6.8 | T11: =INDEX(CachTinhDiem!$A$8:$A$11,MATCH(MAX($P11:$S11),$P11:$S11,0)) -> Đi học | U11: Google | V11: Pinterest
A12: SP0011 | B12: Áo | C12: Áo hoodie nỉ bông màu tím lavender | D12: Unisex | E12: Tím lavender | F12: Trơn | G12: nỉ bông | H12: 5 | I12: 20 | J12: Đông | K12: 4 | L12: 1 | M12: 3 | N12: 2 | O12: Sporty | P12: =ROUND(CachTinhDiem!$B$23*ROUND(1+(SUMPRODUCT(INDEX(CachTinhDiem!$B$8:$E$11,1,0),$K12:$N12)-1)*9/4,1)+CachTinhDiem!$B$24*ROUND(1+(INDEX(CachTinhDiem!$B$15:$E$20,MATCH($O12,CachTinhDiem!$A$15:$A$20,0),1)-1)*9/4,1),1) -> 4.9 | Q12: =ROUND(CachTinhDiem!$B$23*ROUND(1+(SUMPRODUCT(INDEX(CachTinhDiem!$B$8:$E$11,2,0),$K12:$N12)-1)*9/4,1)+CachTinhDiem!$B$24*ROUND(1+(INDEX(CachTinhDiem!$B$15:$E$20,MATCH($O12,CachTinhDiem!$A$15:$A$20,0),2)-1)*9/4,1),1) -> 6.4 | R12: =ROUND(CachTinhDiem!$B$23*ROUND(1+(SUMPRODUCT(INDEX(CachTinhDiem!$B$8:$E$11,3,0),$K12:$N12)-1)*9/4,1)+CachTinhDiem!$B$24*ROUND(1+(INDEX(CachTinhDiem!$B$15:$E$20,MATCH($O12,CachTinhDiem!$A$15:$A$20,0),3)-1)*9/4,1),1) -> 4.9 | S12: =ROUND(CachTinhDiem!$B$23*ROUND(1+(SUMPRODUCT(INDEX(CachTinhDiem!$B$8:$E$11,4,0),$K12:$N12)-1)*9/4,1)+CachTinhDiem!$B$24*ROUND(1+(INDEX(CachTinhDiem!$B$15:$E$20,MATCH($O12,CachTinhDiem!$A$15:$A$20,0),4)-1)*9/4,1),1) -> 2.6 | T12: =INDEX(CachTinhDiem!$A$8:$A$11,MATCH(MAX($P12:$S12),$P12:$S12,0)) -> Xưởng/Công trình | U12: Google | V12: Pinterest
A13: SP0012 | B13: Áo | C13: Áo polo cotton pique màu hồng | D13: Unisex | E13: Hồng | F13: Trơn | G13: cotton pique | H13: 19 | I13: 39 | J13: Xuân, Hạ, Thu | K13: 2 | L13: 5 | M13: 3 | N13: 4 | O13: Casual | P13: =ROUND(CachTinhDiem!$B$23*ROUND(1+(SUMPRODUCT(INDEX(CachTinhDiem!$B$8:$E$11,1,0),$K13:$N13)-1)*9/4,1)+CachTinhDiem!$B$24*ROUND(1+(INDEX(CachTinhDiem!$B$15:$E$20,MATCH($O13,CachTinhDiem!$A$15:$A$20,0),1)-1)*9/4,1),1) -> 8.1 | Q13: =ROUND(CachTinhDiem!$B$23*ROUND(1+(SUMPRODUCT(INDEX(CachTinhDiem!$B$8:$E$11,2,0),$K13:$N13)-1)*9/4,1)+CachTinhDiem!$B$24*ROUND(1+(INDEX(CachTinhDiem!$B$15:$E$20,MATCH($O13,CachTinhDiem!$A$15:$A$20,0),2)-1)*9/4,1),1) -> 6.7 | R13: =ROUND(CachTinhDiem!$B$23*ROUND(1+(SUMPRODUCT(INDEX(CachTinhDiem!$B$8:$E$11,3,0),$K13:$N13)-1)*9/4,1)+CachTinhDiem!$B$24*ROUND(1+(INDEX(CachTinhDiem!$B$15:$E$20,MATCH($O13,CachTinhDiem!$A$15:$A$20,0),3)-1)*9/4,1),1) -> 8.1 | S13: =ROUND(CachTinhDiem!$B$23*ROUND(1+(SUMPRODUCT(INDEX(CachTinhDiem!$B$8:$E$11,4,0),$K13:$N13)-1)*9/4,1)+CachTinhDiem!$B$24*ROUND(1+(INDEX(CachTinhDiem!$B$15:$E$20,MATCH($O13,CachTinhDiem!$A$15:$A$20,0),4)-1)*9/4,1),1) -> 7.1 | T13: =INDEX(CachTinhDiem!$A$8:$A$11,MATCH(MAX($P13:$S13),$P13:$S13,0)) -> Đi học | U13: Google | V13: Pinterest
... A1501: SP1500 | B1501: Dép | C1501: Dép đế bánh mì EVA màu đen | D1501: Unisex | E1501: Đen | F1501: Trơn | G1501: EVA | H1501: 23 | I1501: 40 | J1501: Hạ, Thu | K1501: 1 | L1501: 3 | M1501: 3 | N1501: 2 | O1501: Streetwear | P1501: =ROUND(CachTinhDiem!$B$23*ROUND(1+(SUMPRODUCT(INDEX(CachTinhDiem!$B$8:$E$11,1,0),$K1501:$N1501)-1)*9/4,1)+CachTinhDiem!$B$24*ROUND(1+(INDEX(CachTinhDiem!$B$15:$E$20,MATCH($O1501,CachTinhDiem!$A$15:$A$20,0),1)-1)*9/4,1),1) -> 5.4 | Q1501: =ROUND(CachTinhDiem!$B$23*ROUND(1+(SUMPRODUCT(INDEX(CachTinhDiem!$B$8:$E$11,2,0),$K1501:$N1501)-1)*9/4,1)+CachTinhDiem!$B$24*ROUND(1+(INDEX(CachTinhDiem!$B$15:$E$20,MATCH($O1501,CachTinhDiem!$A$15:$A$20,0),2)-1)*9/4,1),1) -> 4.7 | R1501: =ROUND(CachTinhDiem!$B$23*ROUND(1+(SUMPRODUCT(INDEX(CachTinhDiem!$B$8:$E$11,3,0),$K1501:$N1501)-1)*9/4,1)+CachTinhDiem!$B$24*ROUND(1+(INDEX(CachTinhDiem!$B$15:$E$20,MATCH($O1501,CachTinhDiem!$A$15:$A$20,0),3)-1)*9/4,1),1) -> 5.9 | S1501: =ROUND(CachTinhDiem!$B$23*ROUND(1+(SUMPRODUCT(INDEX(CachTinhDiem!$B$8:$E$11,4,0),$K1501:$N1501)-1)*9/4,1)+CachTinhDiem!$B$24*ROUND(1+(INDEX(CachTinhDiem!$B$15:$E$20,MATCH($O1501,CachTinhDiem!$A$15:$A$20,0),4)-1)*9/4,1),1) -> 3.9 | T1501: =INDEX(CachTinhDiem!$A$8:$A$11,MATCH(MAX($P1501:$S1501),$P1501:$S1501,0)) -> Vẽ ngoại cảnh | U1501: Google | V1501: Pinterest

Sheet DuLieu_ML
A1: ID_SP | B1: Hoàn cảnh | C1: Phong cách | D1: Tmin (°C) | E1: Tmax (°C) | F1: Nhiệt độ ngày (°C) | G1: Giữ ấm | H1: Thoáng khí | I1: Vận động | J1: Chỉn chu | K1: Bước 1: Điểm hoàn cảnh | L1: Bước 2: Điểm phong cách | M1: Bước 3a: Độ lệch nhiệt (°C) | N1: Bước 3b: Hệ số nhiệt độ | O1: Điểm phù hợp (0–10) | P1: Tập
A2: SP1010 | B2: Xưởng/Công trình | C2: Minimalist | D2: 12 | E2: 27 | F2: 39 | G2: 2 | H2: 3 | I2: 3 | J2: 3 | K2: =ROUND(1+(SUMPRODUCT(INDEX(CachTinhDiem!$B$8:$E$11,MATCH($B2,CachTinhDiem!$A$8:$A$11,0),0),$G2:$J2)-1)*9/4,1) -> 5.1 | L2: =ROUND(1+(INDEX(CachTinhDiem!$B$15:$E$20,MATCH($C2,CachTinhDiem!$A$15:$A$20,0),MATCH($B2,CachTinhDiem!$B$14:$E$14,0))-1)*9/4,1) -> 5.5 | M2: =MAX(0,$D2-$F2,$F2-$E2) -> 12 | N2: =MAX(0,1-M2*CachTinhDiem!$B$25) -> 0 | O2: =ROUND((CachTinhDiem!$B$23*K2+CachTinhDiem!$B$24*L2)*N2,1) -> 0 | P2: Test
A3: SP0403 | B3: Vẽ ngoại cảnh | C3: Casual | D3: 19 | E3: 35 | F3: 30 | G3: 2 | H3: 4 | I3: 3 | J3: 3 | K3: =ROUND(1+(SUMPRODUCT(INDEX(CachTinhDiem!$B$8:$E$11,MATCH($B3,CachTinhDiem!$A$8:$A$11,0),0),$G3:$J3)-1)*9/4,1) -> 6.2 | L3: =ROUND(1+(INDEX(CachTinhDiem!$B$15:$E$20,MATCH($C3,CachTinhDiem!$A$15:$A$20,0),MATCH($B3,CachTinhDiem!$B$14:$E$14,0))-1)*9/4,1) -> 10 | M3: =MAX(0,$D3-$F3,$F3-$E3) -> 0 | N3: =MAX(0,1-M3*CachTinhDiem!$B$25) -> 1 | O3: =ROUND((CachTinhDiem!$B$23*K3+CachTinhDiem!$B$24*L3)*N3,1) -> 7.3 | P3: Train
A4: SP1228 | B4: Thuyết trình | C4: Sporty | D4: 18 | E4: 38 | F4: 29 | G4: 2 | H4: 5 | I4: 5 | J4: 3 | K4: =ROUND(1+(SUMPRODUCT(INDEX(CachTinhDiem!$B$8:$E$11,MATCH($B4,CachTinhDiem!$A$8:$A$11,0),0),$G4:$J4)-1)*9/4,1) -> 7.3 | L4: =ROUND(1+(INDEX(CachTinhDiem!$B$15:$E$20,MATCH($C4,CachTinhDiem!$A$15:$A$20,0),MATCH($B4,CachTinhDiem!$B$14:$E$14,0))-1)*9/4,1) -> 1 | M4: =MAX(0,$D4-$F4,$F4-$E4) -> 0 | N4: =MAX(0,1-M4*CachTinhDiem!$B$25) -> 1 | O4: =ROUND((CachTinhDiem!$B$23*K4+CachTinhDiem!$B$24*L4)*N4,1) -> 5.4 | P4: Train
A5: SP1444 | B5: Thuyết trình | C5: Minimalist | D5: 17 | E5: 38 | F5: 30 | G5: 2 | H5: 3 | I5: 4 | J5: 4 | K5: =ROUND(1+(SUMPRODUCT(INDEX(CachTinhDiem!$B$8:$E$11,MATCH($B5,CachTinhDiem!$A$8:$A$11,0),0),$G5:$J5)-1)*9/4,1) -> 7.3 | L5: =ROUND(1+(INDEX(CachTinhDiem!$B$15:$E$20,MATCH($C5,CachTinhDiem!$A$15:$A$20,0),MATCH($B5,CachTinhDiem!$B$14:$E$14,0))-1)*9/4,1) -> 7.8 | M5: =MAX(0,$D5-$F5,$F5-$E5) -> 0 | N5: =MAX(0,1-M5*CachTinhDiem!$B$25) -> 1 | O5: =ROUND((CachTinhDiem!$B$23*K5+CachTinhDiem!$B$24*L5)*N5,1) -> 7.5 | P5: Train
A6: SP0985 | B6: Xưởng/Công trình | C6: Artsy | D6: 5 | E6: 13 | F6: 24 | G6: 5 | H6: 1 | I6: 3 | J6: 3 | K6: =ROUND(1+(SUMPRODUCT(INDEX(CachTinhDiem!$B$8:$E$11,MATCH($B6,CachTinhDiem!$A$8:$A$11,0),0),$G6:$J6)-1)*9/4,1) -> 5.5 | L6: =ROUND(1+(INDEX(CachTinhDiem!$B$15:$E$20,MATCH($C6,CachTinhDiem!$A$15:$A$20,0),MATCH($B6,CachTinhDiem!$B$14:$E$14,0))-1)*9/4,1) -> 3.3 | M6: =MAX(0,$D6-$F6,$F6-$E6) -> 11 | N6: =MAX(0,1-M6*CachTinhDiem!$B$25) -> 0 | O6: =ROUND((CachTinhDiem!$B$23*K6+CachTinhDiem!$B$24*L6)*N6,1) -> 0 | P6: Train
A7: SP0309 | B7: Xưởng/Công trình | C7: Minimalist | D7: 5 | E7: 14 | F7: 33 | G7: 4 | H7: 1 | I7: 2 | J7: 3 | K7: =ROUND(1+(SUMPRODUCT(INDEX(CachTinhDiem!$B$8:$E$11,MATCH($B7,CachTinhDiem!$A$8:$A$11,0),0),$G7:$J7)-1)*9/4,1) -> 3.9 | L7: =ROUND(1+(INDEX(CachTinhDiem!$B$15:$E$20,MATCH($C7,CachTinhDiem!$A$15:$A$20,0),MATCH($B7,CachTinhDiem!$B$14:$E$14,0))-1)*9/4,1) -> 5.5 | M7: =MAX(0,$D7-$F7,$F7-$E7) -> 19 | N7: =MAX(0,1-M7*CachTinhDiem!$B$25) -> 0 | O7: =ROUND((CachTinhDiem!$B$23*K7+CachTinhDiem!$B$24*L7)*N7,1) -> 0 | P7: Train
A8: SP0922 | B8: Vẽ ngoại cảnh | C8: Casual | D8: 5 | E8: 20 | F8: 16 | G8: 4 | H8: 1 | I8: 3 | J8: 3 | K8: =ROUND(1+(SUMPRODUCT(INDEX(CachTinhDiem!$B$8:$E$11,MATCH($B8,CachTinhDiem!$A$8:$A$11,0),0),$G8:$J8)-1)*9/4,1) -> 4.2 | L8: =ROUND(1+(INDEX(CachTinhDiem!$B$15:$E$20,MATCH($C8,CachTinhDiem!$A$15:$A$20,0),MATCH($B8,CachTinhDiem!$B$14:$E$14,0))-1)*9/4,1) -> 10 | M8: =MAX(0,$D8-$F8,$F8-$E8) -> 0 | N8: =MAX(0,1-M8*CachTinhDiem!$B$25) -> 1 | O8: =ROUND((CachTinhDiem!$B$23*K8+CachTinhDiem!$B$24*L8)*N8,1) -> 5.9 | P8: Test
A9: SP0794 | B9: Xưởng/Công trình | C9: Casual | D9: 7 | E9: 28 | F9: 32 | G9: 4 | H9: 2 | I9: 5 | J9: 2 | K9: =ROUND(1+(SUMPRODUCT(INDEX(CachTinhDiem!$B$8:$E$11,MATCH($B9,CachTinhDiem!$A$8:$A$11,0),0),$G9:$J9)-1)*9/4,1) -> 7.5 | L9: =ROUND(1+(INDEX(CachTinhDiem!$B$15:$E$20,MATCH($C9,CachTinhDiem!$A$15:$A$20,0),MATCH($B9,CachTinhDiem!$B$14:$E$14,0))-1)*9/4,1) -> 7.8 | M9: =MAX(0,$D9-$F9,$F9-$E9) -> 4 | N9: =MAX(0,1-M9*CachTinhDiem!$B$25) -> 0.6 | O9: =ROUND((CachTinhDiem!$B$23*K9+CachTinhDiem!$B$24*L9)*N9,1) -> 4.6 | P9: Train
A10: SP0116 | B10: Thuyết trình | C10: Casual | D10: 21 | E10: 38 | F10: 35 | G10: 1 | H10: 5 | I10: 4 | J10: 1 | K10: =ROUND(1+(SUMPRODUCT(INDEX(CachTinhDiem!$B$8:$E$11,MATCH($B10,CachTinhDiem!$A$8:$A$11,0),0),$G10:$J10)-1)*9/4,1) -> 4.2 | L10: =ROUND(1+(INDEX(CachTinhDiem!$B$15:$E$20,MATCH($C10,CachTinhDiem!$A$15:$A$20,0),MATCH($B10,CachTinhDiem!$B$14:$E$14,0))-1)*9/4,1) -> 5.5 | M10: =MAX(0,$D10-$F10,$F10-$E10) -> 0 | N10: =MAX(0,1-M10*CachTinhDiem!$B$25) -> 1 | O10: =ROUND((CachTinhDiem!$B$23*K10+CachTinhDiem!$B$24*L10)*N10,1) -> 4.6 | P10: Test
A11: SP0326 | B11: Thuyết trình | C11: Casual | D11: 5 | E11: 15 | F11: 36 | G11: 4 | H11: 1 | I11: 2 | J11: 4 | K11: =ROUND(1+(SUMPRODUCT(INDEX(CachTinhDiem!$B$8:$E$11,MATCH($B11,CachTinhDiem!$A$8:$A$11,0),0),$G11:$J11)-1)*9/4,1) -> 5.5 | L11: =ROUND(1+(INDEX(CachTinhDiem!$B$15:$E$20,MATCH($C11,CachTinhDiem!$A$15:$A$20,0),MATCH($B11,CachTinhDiem!$B$14:$E$14,0))-1)*9/4,1) -> 5.5 | M11: =MAX(0,$D11-$F11,$F11-$E11) -> 21 | N11: =MAX(0,1-M11*CachTinhDiem!$B$25) -> 0 | O11: =ROUND((CachTinhDiem!$B$23*K11+CachTinhDiem!$B$24*L11)*N11,1) -> 0 | P11: Train
A12: SP0026 | B12: Thuyết trình | C12: Smart Casual | D12: 6 | E12: 17 | F12: 30 | G12: 4 | H12: 2 | I12: 2 | J12: 3 | K12: =ROUND(1+(SUMPRODUCT(INDEX(CachTinhDiem!$B$8:$E$11,MATCH($B12,CachTinhDiem!$A$8:$A$11,0),0),$G12:$J12)-1)*9/4,1) -> 4.6 | L12: =ROUND(1+(INDEX(CachTinhDiem!$B$15:$E$20,MATCH($C12,CachTinhDiem!$A$15:$A$20,0),MATCH($B12,CachTinhDiem!$B$14:$E$14,0))-1)*9/4,1) -> 10 | M12: =MAX(0,$D12-$F12,$F12-$E12) -> 13 | N12: =MAX(0,1-M12*CachTinhDiem!$B$25) -> 0 | O12: =ROUND((CachTinhDiem!$B$23*K12+CachTinhDiem!$B$24*L12)*N12,1) -> 0 | P12: Train
A13: SP0713 | B13: Đi học | C13: Minimalist | D13: 19 | E13: 37 | F13: 27 | G13: 2 | H13: 5 | I13: 4 | J13: 3 | K13: =ROUND(1+(SUMPRODUCT(INDEX(CachTinhDiem!$B$8:$E$11,MATCH($B13,CachTinhDiem!$A$8:$A$11,0),0),$G13:$J13)-1)*9/4,1) -> 7.3 | L13: =ROUND(1+(INDEX(CachTinhDiem!$B$15:$E$20,MATCH($C13,CachTinhDiem!$A$15:$A$20,0),MATCH($B13,CachTinhDiem!$B$14:$E$14,0))-1)*9/4,1) -> 7.8 | M13: =MAX(0,$D13-$F13,$F13-$E13) -> 0 | N13: =MAX(0,1-M13*CachTinhDiem!$B$25) -> 1 | O13: =ROUND((CachTinhDiem!$B$23*K13+CachTinhDiem!$B$24*L13)*N13,1) -> 7.5 | P13: Train
... A6001: SP0487 | B6001: Xưởng/Công trình | C6001: Casual | D6001: 5 | E6001: 12 | F6001: 6 | G6001: 5 | H6001: 1 | I6001: 3 | J6001: 3 | K6001: =ROUND(1+(SUMPRODUCT(INDEX(CachTinhDiem!$B$8:$E$11,MATCH($B6001,CachTinhDiem!$A$8:$A$11,0),0),$G6001:$J6001)-1)*9/4,1) -> 5.5 | L6001: =ROUND(1+(INDEX(CachTinhDiem!$B$15:$E$20,MATCH($C6001,CachTinhDiem!$A$15:$A$20,0),MATCH($B6001,CachTinhDiem!$B$14:$E$14,0))-1)*9/4,1) -> 7.8 | M6001: =MAX(0,$D6001-$F6001,$F6001-$E6001) -> 0 | N6001: =MAX(0,1-M6001*CachTinhDiem!$B$25) -> 1 | O6001: =ROUND((CachTinhDiem!$B$23*K6001+CachTinhDiem!$B$24*L6001)*N6001,1) -> 6.2 | P6001: Train

Sheet CachTinhDiem
A1: CÁCH TÍNH ĐIỂM PHÙ HỢP
A2: Điểm phù hợp (0–10) = ( Tỷ trọng 1 × Bước 1 + Tỷ trọng 2 × Bước 2 ) × Bước 3
A3: Bước 1: món có hợp hoàn cảnh không (từ 4 đặc tính). Bước 2: phong cách của món có hợp hoàn cảnh không. Bước 3: trời hôm nay có nằm trong khoảng nhiệt Tmin–Tmax của món không.
A4: Ô nền vàng, chữ xanh là ô bạn có thể sửa; mọi điểm bên DuLieu_ML tự tính lại.
A6: 1. TRỌNG SỐ 4 ĐẶC TÍNH THEO HOÀN CẢNH (Bước 1)
A7: Hoàn cảnh | B7: Giữ ấm | C7: Thoáng khí | D7: Vận động | E7: Chỉn chu | F7: Tổng (phải = 100%) | G7: Lý do chọn trọng số
A8: Đi học | B8: 0.1 | C8: 0.3 | D8: 0.3 | E8: 0.3 | F8: =SUM(B8:E8) -> 1 | G8: Ngồi nhiều giờ trong lớp: cần thoáng, dễ cử động, gọn gàng vừa phải; giữ ấm chỉ phụ.
A9: Xưởng/Công trình | B9: 0.2 | C9: 0.2 | D9: 0.5 | E9: 0.1 | F9: =SUM(B9:E9) -> 1 | G9: Cử động nhiều, ngồi xổm, vươn tay: ưu tiên Vận động; cần giữ ấm khi làm ngoài trời; ít cần chỉn chu.
A10: Vẽ ngoại cảnh | B10: 0 | C10: 0.3 | D10: 0.5 | E10: 0.2 | F10: =SUM(B10:E10) -> 1 | G10: Ngồi/đứng lâu ngoài nắng, di chuyển nhiều: ưu tiên Vận động và Thoáng khí.
A11: Thuyết trình | B11: 0 | C11: 0.2 | D11: 0.2 | E11: 0.6 | F11: =SUM(B11:E11) -> 1 | G11: Phải chỉnh tề trước hội đồng: ưu tiên Chỉn chu; thoáng và vận động đủ để thoải mái.
A13: 2. ĐỘ HỢP PHONG CÁCH – HOÀN CẢNH, thang 1–5 (Bước 2)
A14: Phong cách | B14: Đi học | C14: Xưởng/Công trình | D14: Vẽ ngoại cảnh | E14: Thuyết trình | F14: Cơ sở (quy ước ăn mặc)
A15: Casual | B15: 5 | C15: 4 | D15: 5 | E15: 3 | F15: Thoải mái, hợp lớp học và đi vẽ; thuyết trình ở mức tạm được.
A16: Smart Casual | B16: 4 | C16: 2 | D16: 2 | E16: 5 | F16: Hợp nhất với thuyết trình/bảo vệ; kém hợp xưởng và ngoài trời.
A17: Sporty | B17: 4 | C17: 5 | D17: 4 | E17: 1 | F17: Dễ cử động nên hợp xưởng; không phù hợp thuyết trình.
A18: Streetwear | B18: 4 | C18: 3 | D18: 4 | E18: 2 | F18: Hợp lớp học và đi vẽ; ít hợp thuyết trình trang trọng.
A19: Minimalist | B19: 4 | C19: 3 | D19: 3 | E19: 4 | F19: Gọn, trung tính: ổn ở mọi nơi, khá hợp thuyết trình.
A20: Artsy | B20: 4 | C20: 2 | D20: 5 | E20: 3 | F20: Hợp nhất với vẽ ngoại cảnh (sinh viên thiết kế/mỹ thuật); không hợp xưởng.
A22: 3. THAM SỐ CHUNG
A23: Tỷ trọng Bước 1 (Điểm hoàn cảnh) | B23: 0.7 | C23: Hoàn cảnh quyết định chính món có dùng được không.
A24: Tỷ trọng Bước 2 (Điểm phong cách) | B24: =1-B23 -> 0.3 | C24: Tự tính = 100% trừ tỷ trọng Bước 1.
A25: Hệ số trừ cho mỗi °C lệch khỏi khoảng nhiệt | B25: 0.1 | C25: Lệch 1°C trừ 10% điểm; lệch 10°C trở lên thì điểm bằng 0 (không mặc nổi). Khái niệm: vùng nhiệt thoải mái của quần áo (ISO 9920, ISO 7730); mức 10% do nhóm đặt.
A27: 4. CÁCH CHẤM 4 ĐẶC TÍNH CỦA MỖI MÓN (thang 1–5, theo chất liệu và kiểu dáng)
A28: Đặc tính | B28: Ý nghĩa | C28: Mức 1 | D28: Mức 3 | E28: Mức 5 | F28: Cơ sở tham chiếu
A29: Giữ ấm | B29: Khả năng giữ nhiệt cơ thể | C29: Rất mỏng: dép, áo linen, váy mỏng | D29: Cotton dày, kaki, jean | E29: Len, nỉ bông, lông vũ, fleece | F29: Độ cách nhiệt của quần áo, đơn vị clo (ISO 9920)
A30: Thoáng khí | B30: Thoát mồ hôi, hơi nước | C30: Da, nylon phủ, PVC | D30: Cotton thường, polyester | E30: Linen, mesh, thun lạnh | F30: Điện trở hơi nước ISO 11092; độ thấm khí ISO 9237
A31: Vận động | B31: Dễ cử động, ngồi xổm, vươn tay | C31: Đầm bó, quần tây cứng, giày da | D31: Jean thường, áo sơ mi | E31: Jogger, thun co giãn, đồ thể thao | F31: Kiểu dáng và độ co giãn (nguyên tắc ergonomics)
A32: Chỉn chu | B32: Phẳng phiu, lịch sự | C32: Đồ thể thao, dép, hoodie | D32: Áo polo, quần jean sạch | E32: Sơ mi, quần tây, blazer, giày da | F32: Quy ước dress code công sở/học thuật
A34: 5. MÁY TÍNH THỬ (sửa các ô vàng để xem điểm thay đổi; ví dụ: áo thun cotton, đi xưởng, trời 12°C)
A35: Hoàn cảnh | B35: Xưởng/Công trình
A36: Phong cách | B36: Streetwear
A37: Tmin của món (°C) | B37: 20
A38: Tmax của món (°C) | B38: 38
A39: Nhiệt độ ngày (°C) | B39: 12
A40: Giữ ấm (1–5) | B40: 2
A41: Thoáng khí (1–5) | B41: 5
A42: Vận động (1–5) | B42: 2
A43: Chỉn chu (1–5) | B43: 2
A45: Bước 1: Điểm hoàn cảnh | B45: =ROUND(1+(INDEX($B$8:$E$11,MATCH($B$35,$A$8:$A$11,0),1)*$B$40+INDEX($B$8:$E$11,MATCH($B$35,$A$8:$A$11,0),2)*$B$41+INDEX($B$8:$E$11,MATCH($B$35,$A$8:$A$11,0),3)*$B$42+INDEX($B$8:$E$11,MATCH($B$35,$A$8:$A$11,0),4)*$B$43-1)*9/4,1) -> 4.6
A46: Bước 2: Điểm phong cách | B46: =ROUND(1+(INDEX($B$15:$E$20,MATCH($B$36,$A$15:$A$20,0),MATCH($B$35,$B$14:$E$14,0))-1)*9/4,1) -> 5.5
...

Sheet KiemChung
A1: KIỂM CHỨNG ĐIỂM BẰNG NGƯỜI CHẤM THẬT (100 tình huống, 25 mỗi hoàn cảnh)
A2: Nhờ 3 bạn sinh viên chấm: "Mặc món này vào hoàn cảnh này, khi trời đang nhiệt độ này, hợp đến mức nào?" thang 0–10 (0: không thể mặc, 1–3: không hợp, 4–6: tạm được, 7–10: hợp). Điền vào ô vàng cột E, F, G.
A3: Khi đưa file cho người chấm, ẩn cột I (Điểm công thức) để họ không bị ảnh hưởng. Ô vàng bên phải cho biết sai số trung bình giữa người chấm và công thức.
A5: ID_SP | B5: Tên trang phục | C5: Hoàn cảnh | D5: Nhiệt độ ngày (°C) | E5: Người chấm 1 | F5: Người chấm 2 | G5: Người chấm 3 | H5: TB người chấm | I5: Điểm công thức | J5: Chênh lệch (tuyệt đối) | L5: Kết quả kiểm chứng
A6: VÍ DỤ (không tính) | B6: Áo sơ mi dài tay cotton màu trắng | C6: Thuyết trình | D6: 28 | E6: 8 | F6: 7 | G6: 8 | H6: =AVERAGE(E6:G6) -> 7.6666667 | I6: 8.2 | J6: =ABS(H6-I6) -> 0.53333333 | L6: Số tình huống đã chấm | M6: =COUNT(H7:H106) -> 0
A7: SP0091 | B7: Áo sơ mi ngắn tay cotton màu hồng | C7: Thuyết trình | D7: 25 | H7: =IF(COUNT(E7:G7)=0,"",AVERAGE(E7:G7)) | I7: =SUMIFS(DuLieu_ML!$O$2:$O$6001,DuLieu_ML!$A$2:$A$6001,$A7,DuLieu_ML!$B$2:$B$6001,$C7) -> 7.1 | J7: =IF(H7="","",ABS(H7-I7)) | L7: Sai số trung bình (MAE) | M7: =IFERROR(AVERAGE(J7:J106),"chưa có dữ liệu") -> chưa có dữ liệu
A8: SP0120 | B8: Áo thun tay dài basic modal màu trắng | C8: Thuyết trình | D8: 9 | H8: =IF(COUNT(E8:G8)=0,"",AVERAGE(E8:G8)) | I8: =SUMIFS(DuLieu_ML!$O$2:$O$6001,DuLieu_ML!$A$2:$A$6001,$A8,DuLieu_ML!$B$2:$B$6001,$C8) -> 2 | J8: =IF(H8="","",ABS(H8-I8)) | L8: Hệ số tương quan | M8: =IFERROR(CORREL(H7:H106,I7:I106),"chưa có dữ liệu") -> chưa có dữ liệu
A9: SP0134 | B9: Áo sơ mi dài tay linen màu vàng | C9: Thuyết trình | D9: 32 | H9: =IF(COUNT(E9:G9)=0,"",AVERAGE(E9:G9)) | I9: =SUMIFS(DuLieu_ML!$O$2:$O$6001,DuLieu_ML!$A$2:$A$6001,$A9,DuLieu_ML!$B$2:$B$6001,$C9) -> 7.5 | J9: =IF(H9="","",ABS(H9-I9))
A10: SP0166 | B10: Áo sơ mi ngắn tay cotton họa tiết kẻ sọc xanh trắng | C10: Thuyết trình | D10: 32 | H10: =IF(COUNT(E10:G10)=0,"",AVERAGE(E10:G10)) | I10: =SUMIFS(DuLieu_ML!$O$2:$O$6001,DuLieu_ML!$A$2:$A$6001,$A10,DuLieu_ML!$B$2:$B$6001,$C10) -> 6.8 | J10: =IF(H10="","",ABS(H10-I10)) | L10: Gợi ý: MAE dưới 1.5 điểm và tương quan trên 0.7 là công thức khá sát cảm nhận người chấm. Nếu lệch nhiều, chỉnh trọng số ở sheet CachTinhDiem.
A11: SP0270 | B11: Áo len cardigan mohair màu đen | C11: Thuyết trình | D11: 37 | H11: =IF(COUNT(E11:G11)=0,"",AVERAGE(E11:G11)) | I11: =SUMIFS(DuLieu_ML!$O$2:$O$6001,DuLieu_ML!$A$2:$A$6001,$A11,DuLieu_ML!$B$2:$B$6001,$C11) -> 0 | J11: =IF(H11="","",ABS(H11-I11))
A12: SP0378 | B12: Áo henley cotton màu xanh lá | C12: Thuyết trình | D12: 40 | H12: =IF(COUNT(E12:G12)=0,"",AVERAGE(E12:G12)) | I12: =SUMIFS(DuLieu_ML!$O$2:$O$6001,DuLieu_ML!$A$2:$A$6001,$A12,DuLieu_ML!$B$2:$B$6001,$C12) -> 2.9 | J12: =IF(H12="","",ABS(H12-I12))
A13: SP0537 | B13: Áo khoác parka cotton canvas màu xanh olive | C13: Thuyết trình | D13: 31 | H13: =IF(COUNT(E13:G13)=0,"",AVERAGE(E13:G13)) | I13: =SUMIFS(DuLieu_ML!$O$2:$O$6001,DuLieu_ML!$A$2:$A$6001,$A13,DuLieu_ML!$B$2:$B$6001,$C13) -> 0 | J13: =IF(H13="","",ABS(H13-I13))
A14: SP0576 | B14: Áo khoác da da bò màu đen | C14: Thuyết trình | D14: 26 | H14: =IF(COUNT(E14:G14)=0,"",AVERAGE(E14:G14)) | I14: =SUMIFS(DuLieu_ML!$O$2:$O$6001,DuLieu_ML!$A$2:$A$6001,$A14,DuLieu_ML!$B$2:$B$6001,$C14) -> 1.9 | J14: =IF(H14="","",ABS(H14-I14))
A15: SP0577 | B15: Áo cardigan dài mohair màu xanh dương | C15: Thuyết trình | D15: 38 | H15: =IF(COUNT(E15:G15)=0,"",AVERAGE(E15:G15)) | I15: =SUMIFS(DuLieu_ML!$O$2:$O$6001,DuLieu_ML!$A$2:$A$6001,$A15,DuLieu_ML!$B$2:$B$6001,$C15) -> 0 | J15: =IF(H15="","",ABS(H15-I15))
A16: SP0603 | B16: Áo khoác dạ màu trắng | C16: Thuyết trình | D16: 39 | H16: =IF(COUNT(E16:G16)=0,"",AVERAGE(E16:G16)) | I16: =SUMIFS(DuLieu_ML!$O$2:$O$6001,DuLieu_ML!$A$2:$A$6001,$A16,DuLieu_ML!$B$2:$B$6001,$C16) -> 0 | J16: =IF(H16="","",ABS(H16-I16))
A17: SP0669 | B17: Quần nỉ màu xám tro | C17: Thuyết trình | D17: 38 | H17: =IF(COUNT(E17:G17)=0,"",AVERAGE(E17:G17)) | I17: =SUMIFS(DuLieu_ML!$O$2:$O$6001,DuLieu_ML!$A$2:$A$6001,$A17,DuLieu_ML!$B$2:$B$6001,$C17) -> 0 | J17: =IF(H17="","",ABS(H17-I17))
A18: SP0791 | B18: Quần kaki ống đứng màu be | C18: Thuyết trình | D18: 21 | H18: =IF(COUNT(E18:G18)=0,"",AVERAGE(E18:G18)) | I18: =SUMIFS(DuLieu_ML!$O$2:$O$6001,DuLieu_ML!$A$2:$A$6001,$A18,DuLieu_ML!$B$2:$B$6001,$C18) -> 6.9 | J18: =IF(H18="","",ABS(H18-I18))
A19: SP0836 | B19: Quần cargo kaki màu xanh mint | C19: Thuyết trình | D19: 28 | H19: =IF(COUNT(E19:G19)=0,"",AVERAGE(E19:G19)) | I19: =SUMIFS(DuLieu_ML!$O$2:$O$6001,DuLieu_ML!$A$2:$A$6001,$A19,DuLieu_ML!$B$2:$B$6001,$C19) -> 4 | J19: =IF(H19="","",ABS(H19-I19))
A20: SP0895 | B20: Quần legging thun cotton màu hồng pastel | C20: Thuyết trình | D20: 29 | H20: =IF(COUNT(E20:G20)=0,"",AVERAGE(E20:G20)) | I20: =SUMIFS(DuLieu_ML!$O$2:$O$6001,DuLieu_ML!$A$2:$A$6001,$A20,DuLieu_ML!$B$2:$B$6001,$C20) -> 4.8 | J20: =IF(H20="","",ABS(H20-I20))
A21: SP0926 | B21: Quần chinos kaki màu trắng | C21: Thuyết trình | D21: 35 | H21: =IF(COUNT(E21:G21)=0,"",AVERAGE(E21:G21)) | I21: =SUMIFS(DuLieu_ML!$O$2:$O$6001,DuLieu_ML!$A$2:$A$6001,$A21,DuLieu_ML!$B$2:$B$6001,$C21) -> 4.9 | J21: =IF(H21="","",ABS(H21-I21))
A22: SP0932 | B22: Quần nỉ cotton french terry màu xanh lá | C22: Thuyết trình | D22: 33 | H22: =IF(COUNT(E22:G22)=0,"",AVERAGE(E22:G22)) | I22: =SUMIFS(DuLieu_ML!$O$2:$O$6001,DuLieu_ML!$A$2:$A$6001,$A22,DuLieu_ML!$B$2:$B$6001,$C22) -> 0 | J22: =IF(H22="","",ABS(H22-I22))
... A106: SP1492 | B106: Dép sandal thể thao nylon màu khaki | C106: Đi học | D106: 23 | H106: =IF(COUNT(E106:G106)=0,"",AVERAGE(E106:G106)) | I106: =SUMIFS(DuLieu_ML!$O$2:$O$6001,DuLieu_ML!$A$2:$A$6001,$A106,DuLieu_ML!$B$2:$B$6001,$C106) -> 7 | J106: =IF(H106="","",ABS(H106-I106))

Sheet ThongKe
A1: THỐNG KÊ NHANH (tự tính từ DuLieu_ML và MonDo)
A3: Hoàn cảnh (DuLieu_ML) | B3: Số dòng | C3: Tỷ lệ | D3: Điểm TB
A4: Đi học | B4: =COUNTIF(DuLieu_ML!$B$2:$B$6001,A4) -> 1500 | C4: =B4/COUNTA(DuLieu_ML!$B$2:$B$6001) -> 0.25 | D4: =AVERAGEIF(DuLieu_ML!$B$2:$B$6001,A4,DuLieu_ML!$O$2:$O$6001) -> 4.1242667
A5: Xưởng/Công trình | B5: =COUNTIF(DuLieu_ML!$B$2:$B$6001,A5) -> 1500 | C5: =B5/COUNTA(DuLieu_ML!$B$2:$B$6001) -> 0.25 | D5: =AVERAGEIF(DuLieu_ML!$B$2:$B$6001,A5,DuLieu_ML!$O$2:$O$6001) -> 3.608
A6: Vẽ ngoại cảnh | B6: =COUNTIF(DuLieu_ML!$B$2:$B$6001,A6) -> 1500 | C6: =B6/COUNTA(DuLieu_ML!$B$2:$B$6001) -> 0.25 | D6: =AVERAGEIF(DuLieu_ML!$B$2:$B$6001,A6,DuLieu_ML!$O$2:$O$6001) -> 4.0363333
A7: Thuyết trình | B7: =COUNTIF(DuLieu_ML!$B$2:$B$6001,A7) -> 1500 | C7: =B7/COUNTA(DuLieu_ML!$B$2:$B$6001) -> 0.25 | D7: =AVERAGEIF(DuLieu_ML!$B$2:$B$6001,A7,DuLieu_ML!$O$2:$O$6001) -> 3.6962
A9: Phong cách (DuLieu_ML) | B9: Số dòng | C9: Tỷ lệ | D9: Điểm TB
A10: Casual | B10: =COUNTIF(DuLieu_ML!$C$2:$C$6001,A10) -> 1408 | C10: =B10/COUNTA(DuLieu_ML!$C$2:$C$6001) -> 0.23466667 | D10: =AVERAGEIF(DuLieu_ML!$C$2:$C$6001,A10,DuLieu_ML!$O$2:$O$6001) -> 4.0315341
A11: Smart Casual | B11: =COUNTIF(DuLieu_ML!$C$2:$C$6001,A11) -> 1448 | C11: =B11/COUNTA(DuLieu_ML!$C$2:$C$6001) -> 0.24133333 | D11: =AVERAGEIF(DuLieu_ML!$C$2:$C$6001,A11,DuLieu_ML!$O$2:$O$6001) -> 4.0198895
A12: Sporty | B12: =COUNTIF(DuLieu_ML!$C$2:$C$6001,A12) -> 920 | C12: =B12/COUNTA(DuLieu_ML!$C$2:$C$6001) -> 0.15333333 | D12: =AVERAGEIF(DuLieu_ML!$C$2:$C$6001,A12,DuLieu_ML!$O$2:$O$6001) -> 4.3853261
A13: Streetwear | B13: =COUNTIF(DuLieu_ML!$C$2:$C$6001,A13) -> 748 | C13: =B13/COUNTA(DuLieu_ML!$C$2:$C$6001) -> 0.12466667 | D13: =AVERAGEIF(DuLieu_ML!$C$2:$C$6001,A13,DuLieu_ML!$O$2:$O$6001) -> 3.6791444
A14: Minimalist | B14: =COUNTIF(DuLieu_ML!$C$2:$C$6001,A14) -> 768 | C14: =B14/COUNTA(DuLieu_ML!$C$2:$C$6001) -> 0.128 | D14: =AVERAGEIF(DuLieu_ML!$C$2:$C$6001,A14,DuLieu_ML!$O$2:$O$6001) -> 3.4453125
A15: Artsy | B15: =COUNTIF(DuLieu_ML!$C$2:$C$6001,A15) -> 708 | C15: =B15/COUNTA(DuLieu_ML!$C$2:$C$6001) -> 0.118 | D15: =AVERAGEIF(DuLieu_ML!$C$2:$C$6001,A15,DuLieu_ML!$O$2:$O$6001) -> 3.2026836
A17: Tập | B17: Số dòng | C17: Tỷ lệ
A18: Train | B18: =COUNTIF(DuLieu_ML!$P$2:$P$6001,A18) -> 4836 | C18: =B18/COUNTA(DuLieu_ML!$P$2:$P$6001) -> 0.806
A19: Test | B19: =COUNTIF(DuLieu_ML!$P$2:$P$6001,A19) -> 1164 | C19: =B19/COUNTA(DuLieu_ML!$P$2:$P$6001) -> 0.194
A21: Phân bố điểm phù hợp | B21: Số dòng | C21: Tỷ lệ
A22: Bằng 0 | B22: =COUNTIF(DuLieu_ML!$O$2:$O$6001,0) -> 1276 | C22: =B22/COUNT(DuLieu_ML!$O$2:$O$6001) -> 0.21266667
A23: Từ 0.1 đến 2 | B23: =COUNTIFS(DuLieu_ML!$O$2:$O$6001,">0",DuLieu_ML!$O$2:$O$6001,"<=2") -> 541 | C23: =B23/COUNT(DuLieu_ML!$O$2:$O$6001) -> 0.090166667
A24: Từ 2.1 đến 4 | B24: =COUNTIFS(DuLieu_ML!$O$2:$O$6001,">2",DuLieu_ML!$O$2:$O$6001,"<=4") -> 954 | C24: =B24/COUNT(DuLieu_ML!$O$2:$O$6001) -> 0.159
A25: Từ 4.1 đến 6 | B25: =COUNTIFS(DuLieu_ML!$O$2:$O$6001,">4",DuLieu_ML!$O$2:$O$6001,"<=6") -> 1649 | C25: =B25/COUNT(DuLieu_ML!$O$2:$O$6001) -> 0.27483333
A26: Từ 6.1 đến 8 | B26: =COUNTIFS(DuLieu_ML!$O$2:$O$6001,">6",DuLieu_ML!$O$2:$O$6001,"<=8") -> 1321 | C26: =B26/COUNT(DuLieu_ML!$O$2:$O$6001) -> 0.22016667
A27: Từ 8.1 đến 10 | B27: =COUNTIFS(DuLieu_ML!$O$2:$O$6001,">8",DuLieu_ML!$O$2:$O$6001,"<=10") -> 259 | C27: =B27/COUNT(DuLieu_ML!$O$2:$O$6001) -> 0.043166667
A29: Chỉ số | B29: Giá trị
A30: Điểm nhỏ nhất | B30: =MIN(DuLieu_ML!$O$2:$O$6001) -> 0
A31: Điểm lớn nhất | B31: =MAX(DuLieu_ML!$O$2:$O$6001) -> 9.4
A32: Điểm trung bình | B32: =AVERAGE(DuLieu_ML!$O$2:$O$6001) -> 3.8662
A33: Độ lệch chuẩn | B33: =STDEV(DuLieu_ML!$O$2:$O$6001) -> 2.7205516
A34: Tỷ lệ dòng có trời nằm trong khoảng nhiệt của món | B34: =COUNTIF(DuLieu_ML!$N$2:$N$6001,1)/COUNT(DuLieu_ML!$N$2:$N$6001) -> 0.46416667
A36: Giới tính (MonDo) | B36: Số món | C36: Tỷ lệ
A37: Nam | B37: =COUNTIF(MonDo!$D$2:$D$1501,A37) -> 600 | C37: =B37/COUNTA(MonDo!$D$2:$D$1501) -> 0.4
A38: Nữ | B38: =COUNTIF(MonDo!$D$2:$D$1501,A38) -> 600 | C38: =B38/COUNTA(MonDo!$D$2:$D$1501) -> 0.4
A39: Unisex | B39: =COUNTIF(MonDo!$D$2:$D$1501,A39) -> 300 | C39: =B39/COUNTA(MonDo!$D$2:$D$1501) -> 0.2
A41: Loại TP (MonDo) | B41: Số món | C41: Tỷ lệ
A42: Áo | B42: =COUNTIF(MonDo!$B$2:$B$1501,A42) -> 440 | C42: =B42/COUNTA(MonDo!$B$2:$B$1501) -> 0.29333333
A43: Áo khoác | B43: =COUNTIF(MonDo!$B$2:$B$1501,A43) -> 220 | C43: =B43/COUNTA(MonDo!$B$2:$B$1501) -> 0.14666667
A44: Quần | B44: =COUNTIF(MonDo!$B$2:$B$1501,A44) -> 300 | C44: =B44/COUNTA(MonDo!$B$2:$B$1501) -> 0.2
A45: Chân Váy | B45: =COUNTIF(MonDo!$B$2:$B$1501,A45) -> 90 | C45: =B45/COUNTA(MonDo!$B$2:$B$1501) -> 0.06
A46: Đầm | B46: =COUNTIF(MonDo!$B$2:$B$1501,A46) -> 110 | C46: =B46/COUNTA(MonDo!$B$2:$B$1501) -> 0.073333333
A47: Giày | B47: =COUNTIF(MonDo!$B$2:$B$1501,A47) -> 220 | C47: =B47/COUNTA(MonDo!$B$2:$B$1501) -> 0.14666667
...
